Workbook

Sheet Overview & Stats
A1: Striver's A2Z DSA Sheet - Curriculum Dashboard
A2: High-level module distribution, problem counts, and study roadmap tracking
A4: Step # | B4: Module Name | C4: Topic Focus | D4: Problem Count | E4: Status
A5: Step 1 | B5: Learn the Basics | C5: Language syntax, Basic Maths, Recursion, Hashing, Patterns | D5: =COUNTIF('All 476 Problems'!C5:C480, "*Step 1*") | E5: In Progress
A6: Step 2 | B6: Learn Important Sorting Techniques | C6: Selection, Bubble, Insertion, Merge, Quick Sort | D6: =COUNTIF('All 476 Problems'!C5:C480, "*Step 2*") | E6: In Progress
A7: Step 3 | B7: Solve Problems on Arrays | C7: Easy, Medium, and Hard array manipulation & algorithmic patterns | D7: =COUNTIF('All 476 Problems'!C5:C480, "*Step 3*") | E7: In Progress
A8: Step 4 | B8: Binary Search | C8: 1D Binary Search, Search Space/Answers, 2D Array Matrix Search | D8: =COUNTIF('All 476 Problems'!C5:C480, "*Step 4*") | E8: In Progress
A9: Step 5 | B9: Strings [Basic and Medium] | C9: String transformations, palindrome, frequency, parsing | D9: =COUNTIF('All 476 Problems'!C5:C480, "*Step 5*") | E9: In Progress
A10: Step 6 | B10: Learn LinkedList [Singly, Doubly, Medium, Hard] | C10: 1D LL, Doubly LL, fast/slow pointer, reversal, flattening, cloning | D10: =COUNTIF('All 476 Problems'!C5:C480, "*Step 6*") | E10: In Progress
A11: Step 7 | B11: Recursion [Pattern-wise] | C11: Subsequences, combination sums, backtracking, N-Queens, Sudoku | D11: =COUNTIF('All 476 Problems'!C5:C480, "*Step 7*") | E11: In Progress
A12: Step 8 | B12: Bit Manipulation | C12: Bitwise operators, power sets, XOR properties, prime sieves | D12: =COUNTIF('All 476 Problems'!C5:C480, "*Step 8*") | E12: In Progress
A13: Step 9 | B13: Stack and Queues | C13: Monotonic Stack/Queue, conversions, LRU/LFU cache, histograms | D13: =COUNTIF('All 476 Problems'!C5:C480, "*Step 9*") | E13: In Progress
A14: Step 10 | B14: Sliding Window & Two Pointer | C14: Substrings with conditions, variable and fixed size window patterns | D14: =COUNTIF('All 476 Problems'!C5:C480, "*Step 10*") | E14: In Progress
A15: Step 11 | B15: Heaps [Learning, Medium, Hard] | C15: Priority Queues, Top-K, Median from Data Stream, K-sorted lists | D15: =COUNTIF('All 476 Problems'!C5:C480, "*Step 11*") | E15: In Progress
A16: Step 12 | B16: Greedy Algorithms | C16: Activity selection, interval scheduling, knapsack, Jump Game | D16: =COUNTIF('All 476 Problems'!C5:C480, "*Step 12*") | E16: In Progress
A17: Step 13 | B17: Binary Trees | C17: Traversals, Views, LCA, Width, Burn Tree, Construction, Morris traversal | D17: =COUNTIF('All 476 Problems'!C5:C480, "*Step 13*") | E17: In Progress
A18: Step 14 | B18: Binary Search Trees | C18: BST validation, Floor/Ceil, Iterator, Correcting inverted nodes | D18: =COUNTIF('All 476 Problems'!C5:C480, "*Step 14*") | E18: In Progress
A19: Step 15 | B19: Graphs | C19: BFS/DFS, Topological Sort, Dijkstra, Bellman-Ford, Floyd-Warshall, DSU, MST | D19: =COUNTIF('All 476 Problems'!C5:C480, "*Step 15*") | E19: In Progress
A20: Step 16 | B20: Dynamic Programming | C20: 1D, Grids, Subsequences, Strings, Stocks, LIS, MCM, Partition | D20: =COUNTIF('All 476 Problems'!C5:C480, "*Step 16*") | E20: In Progress
A21: Step 17 | B21: Tries | C21: Prefix tree insert/search, word dictionary, XOR optimization | D21: =COUNTIF('All 476 Problems'!C5:C480, "*Step 17*") | E21: In Progress
A22: Step 18 | B22: Advanced Strings | C22: KMP, Rabin-Karp, Z-Algorithm, Longest prefix matching | D22: =COUNTIF('All 476 Problems'!C5:C480, "*Step 18*") | E22: In Progress
A23: Total | B23: All 18 Major Steps | C23: Full A2Z Roadmap Syllabus | D23: =SUM(D5:D22) | E23: Master Tracker

Sheet All 476 Problems
A1: Striver's A2Z DSA Sheet - Complete 476 Problem Master Tracker
A2: Systematic syllabus mapping every concept and practice problem with its corresponding LeetCode problem link
A4: ID | B4: Status | C4: Step / Phase | D4: Topic / Sub-step | E4: Problem Name | F4: Difficulty | G4: LeetCode URL | H4: YouTube Solution Link
A5: 1 | B5: Todo | C5: Step 1: Learn the Basics | D5: Basic Maths | E5: Count Digits | F5: Easy | G5: =HYPERLINK("https://leetcode.com/problems/count-digits/", "LeetCode Practice") | H5: =HYPERLINK("https://www.youtube.com/results?search_query=takeUforward+Count+Digits", "YouTube Video")
A6: 2 | B6: Todo | C6: Step 1: Learn the Basics | D6: Basic Maths | E6: Reverse a Number | F6: Medium | G6: =HYPERLINK("https://leetcode.com/problems/reverse-integer/", "LeetCode Practice") | H6: =HYPERLINK("https://www.youtube.com/results?search_query=takeUforward+Reverse+a+Number", "YouTube Video")
A7: 3 | B7: Todo | C7: Step 1: Learn the Basics | D7: Basic Maths | E7: Check Palindrome | F7: Easy | G7: =HYPERLINK("https://leetcode.com/problems/palindrome-number/", "LeetCode Practice") | H7: =HYPERLINK("https://www.youtube.com/results?search_query=takeUforward+Check+Palindrome", "YouTube Video")
A8: 4 | B8: Todo | C8: Step 1: Learn the Basics | D8: Basic Maths | E8: GCD Or HCF | F8: Easy | G8: =HYPERLINK("https://leetcode.com/problems/find-greatest-common-divisor-of-array/", "LeetCode Practice") | H8: =HYPERLINK("https://www.youtube.com/results?search_query=takeUforward+GCD+Or+HCF", "YouTube Video")
A9: 5 | B9: Todo | C9: Step 1: Learn the Basics | D9: Basic Maths | E9: Armstrong Numbers | F9: Easy | G9: =HYPERLINK("https://leetcode.com/problems/armstrong-number/", "LeetCode Practice") | H9: =HYPERLINK("https://www.youtube.com/results?search_query=takeUforward+Armstrong+Numbers", "YouTube Video")
A10: 6 | B10: Todo | C10: Step 1: Learn the Basics | D10: Basic Maths | E10: Print all Divisors | F10: Easy | G10: =HYPERLINK("https://leetcode.com/problems/three-divisors/", "LeetCode Practice") | H10: =HYPERLINK("https://www.youtube.com/results?search_query=takeUforward+Print+all+Divisors", "YouTube Video")
A11: 7 | B11: Todo | C11: Step 1: Learn the Basics | D11: Basic Maths | E11: Check for Prime | F11: Easy | G11: =HYPERLINK("https://leetcode.com/problems/count-primes/", "LeetCode Practice") | H11: =HYPERLINK("https://www.youtube.com/results?search_query=takeUforward+Check+for+Prime", "YouTube Video")
A12: 8 | B12: Todo | C12: Step 1: Learn the Basics | D12: Basic Recursion | E12: Understand Recursion by Print 1 to N | F12: Easy | G12: =HYPERLINK("https://leetcode.com/problems/print-in-order/", "LeetCode Practice") | H12: =HYPERLINK("https://www.youtube.com/results?search_query=takeUforward+Understand+Recursion+by+Print+1+to+N", "YouTube Video")
A13: 9 | B13: Todo | C13: Step 1: Learn the Basics | D13: Basic Recursion | E13: Print N to 1 using Recursion | F13: Easy | G13: =HYPERLINK("https://leetcode.com/problems/fizz-buzz/", "LeetCode Practice") | H13: =HYPERLINK("https://www.youtube.com/results?search_query=takeUforward+Print+N+to+1+using+Recursion", "YouTube Video")
A14: 10 | B14: Todo | C14: Step 1: Learn the Basics | D14: Basic Recursion | E14: Sum of first N numbers | F14: Easy | G14: =HYPERLINK("https://leetcode.com/problems/running-sum-of-1d-array/", "LeetCode Practice") | H14: =HYPERLINK("https://www.youtube.com/results?search_query=takeUforward+Sum+of+first+N+numbers", "YouTube Video")
A15: 11 | B15: Todo | C15: Step 1: Learn the Basics | D15: Basic Recursion | E15: Factorial of N numbers | F15: Easy | G15: =HYPERLINK("https://leetcode.com/problems/climbing-stairs/", "LeetCode Practice") | H15: =HYPERLINK("https://www.youtube.com/results?search_query=takeUforward+Factorial+of+N+numbers", "YouTube Video")
A16: 12 | B16: Todo | C16: Step 1: Learn the Basics | D16: Basic Recursion | E16: Reverse an Array | F16: Easy | G16: =HYPERLINK("https://leetcode.com/problems/reverse-string/", "LeetCode Practice") | H16: =HYPERLINK("https://www.youtube.com/results?search_query=takeUforward+Reverse+an+Array", "YouTube Video")
A17: 13 | B17: Todo | C17: Step 1: Learn the Basics | D17: Basic Recursion | E17: Check if a String is Palindrome | F17: Easy | G17: =HYPERLINK("https://leetcode.com/problems/valid-palindrome/", "LeetCode Practice") | H17: =HYPERLINK("https://www.youtube.com/results?search_query=takeUforward+Check+if+a+String+is+Palindrome", "YouTube Video")
A18: 14 | B18: Todo | C18: Step 1: Learn the Basics | D18: Basic Recursion | E18: Fibonacci Number | F18: Easy | G18: =HYPERLINK("https://leetcode.com/problems/fibonacci-number/", "LeetCode Practice") | H18: =HYPERLINK("https://www.youtube.com/results?search_query=takeUforward+Fibonacci+Number", "YouTube Video")
A19: 15 | B19: Todo | C19: Step 1: Learn the Basics | D19: Basic Hashing | E19: Counting Frequencies of Array Elements | F19: Easy | G19: =HYPERLINK("https://leetcode.com/problems/frequency-of-the-most-frequent-element/", "LeetCode Practice") | H19: =HYPERLINK("https://www.youtube.com/results?search_query=takeUforward+Counting+Frequencies+of+Array+Elements", "YouTube Video")
A20: 16 | B20: Todo | C20: Step 1: Learn the Basics | D20: Basic Hashing | E20: Find the Highest/Lowest Frequency Element | F20: Easy | G20: =HYPERLINK("https://leetcode.com/problems/top-k-frequent-elements/", "LeetCode Practice") | H20: =HYPERLINK("https://www.youtube.com/results?search_query=takeUforward+Find+the+Highest+Lowest+Frequency+Element", "YouTube Video")
A21: 17 | B21: Todo | C21: Step 2: Sorting Techniques | D21: Sorting-I | E21: Selection Sort | F21: Easy | G21: =HYPERLINK("https://leetcode.com/problems/sort-an-array/", "LeetCode Practice") | H21: =HYPERLINK("https://www.youtube.com/results?search_query=takeUforward+Selection+Sort", "YouTube Video")
A22: 18 | B22: Todo | C22: Step 2: Sorting Techniques | D22: Sorting-I | E22: Bubble Sort | F22: Easy | G22: =HYPERLINK("https://leetcode.com/problems/sort-an-array/", "LeetCode Practice") | H22: =HYPERLINK("https://www.youtube.com/results?search_query=takeUforward+Bubble+Sort", "YouTube Video")
A23: 19 | B23: Todo | C23: Step 2: Sorting Techniques | D23: Sorting-I | E23: Insertion Sort | F23: Easy | G23: =HYPERLINK("https://leetcode.com/problems/insertion-sort-list/", "LeetCode Practice") | H23: =HYPERLINK("https://www.youtube.com/results?search_query=takeUforward+Insertion+Sort", "YouTube Video")
A24: 20 | B24: Todo | C24: Step 2: Sorting Techniques | D24: Sorting-II | E24: Merge Sort | F24: Medium | G24: =HYPERLINK("https://leetcode.com/problems/sort-an-array/", "LeetCode Practice") | H24: =HYPERLINK("https://www.youtube.com/results?search_query=takeUforward+Merge+Sort", "YouTube Video")
A25: 21 | B25: Todo | C25: Step 2: Sorting Techniques | D25: Sorting-II | E25: Recursive Bubble Sort | F25: Easy | G25: =HYPERLINK("https://leetcode.com/problems/sort-colors/", "LeetCode Practice") | H25: =HYPERLINK("https://www.youtube.com/results?search_query=takeUforward+Recursive+Bubble+Sort", "YouTube Video")
A26: 22 | B26: Todo | C26: Step 2: Sorting Techniques | D26: Sorting-II | E26: Recursive Insertion Sort | F26: Easy | G26: =HYPERLINK("https://leetcode.com/problems/sort-an-array/", "LeetCode Practice") | H26: =HYPERLINK("https://www.youtube.com/results?search_query=takeUforward+Recursive+Insertion+Sort", "YouTube Video")
A27: 23 | B27: Todo | C27: Step 2: Sorting Techniques | D27: Sorting-II | E27: Quick Sort | F27: Medium | G27: =HYPERLINK("https://leetcode.com/problems/sort-an-array/", "LeetCode Practice") | H27: =HYPERLINK("https://www.youtube.com/results?search_query=takeUforward+Quick+Sort", "YouTube Video")
A28: 24 | B28: Todo | C28: Step 3: Arrays | D28: Easy | E28: Largest Element in an Array | F28: Easy | G28: =HYPERLINK("https://leetcode.com/problems/third-maximum-number/", "LeetCode Practice") | H28: =HYPERLINK("https://www.youtube.com/results?search_query=takeUforward+Largest+Element+in+an+Array", "YouTube Video")
A29: 25 | B29: Todo | C29: Step 3: Arrays | D29: Easy | E29: Second Largest Element in an Array | F29: Easy | G29: =HYPERLINK("https://leetcode.com/problems/second-minimum-node-in-a-binary-tree/", "LeetCode Practice") | H29: =HYPERLINK("https://www.youtube.com/results?search_query=takeUforward+Second+Largest+Element+in+an+Array", "YouTube Video")
A30: 26 | B30: Todo | C30: Step 3: Arrays | D30: Easy | E30: Check if the array is sorted | F30: Easy | G30: =HYPERLINK("https://leetcode.com/problems/check-if-array-is-sorted-and-rotated/", "LeetCode Practice") | H30: =HYPERLINK("https://www.youtube.com/results?search_query=takeUforward+Check+if+the+array+is+sorted", "YouTube Video")
A31: 27 | B31: Todo | C31: Step 3: Arrays | D31: Easy | E31: Remove duplicates from Sorted array | F31: Easy | G31: =HYPERLINK("https://leetcode.com/problems/remove-duplicates-from-sorted-array/", "LeetCode Practice") | H31: =HYPERLINK("https://www.youtube.com/results?search_query=takeUforward+Remove+duplicates+from+Sorted+array", "YouTube Video")
A32: 28 | B32: Todo | C32: Step 3: Arrays | D32: Easy | E32: Left Rotate an array by one place | F32: Easy | G32: =HYPERLINK("https://leetcode.com/problems/rotate-array/", "LeetCode Practice") | H32: =HYPERLINK("https://www.youtube.com/results?search_query=takeUforward+Left+Rotate+an+array+by+one+place", "YouTube Video")
A33: 29 | B33: Todo | C33: Step 3: Arrays | D33: Easy | E33: Left rotate an array by D places | F33: Medium | G33: =HYPERLINK("https://leetcode.com/problems/rotate-array/", "LeetCode Practice") | H33: =HYPERLINK("https://www.youtube.com/results?search_query=takeUforward+Left+rotate+an+array+by+D+places", "YouTube Video")
A34: 30 | B34: Todo | C34: Step 3: Arrays | D34: Easy | E34: Move Zeros to end | F34: Easy | G34: =HYPERLINK("https://leetcode.com/problems/move-zeroes/", "LeetCode Practice") | H34: =HYPERLINK("https://www.youtube.com/results?search_query=takeUforward+Move+Zeros+to+end", "YouTube Video")
A35: 31 | B35: Todo | C35: Step 3: Arrays | D35: Easy | E35: Linear Search | F35: Easy | G35: =HYPERLINK("https://leetcode.com/problems/find-target-indices-after-sorting-array/", "LeetCode Practice") | H35: =HYPERLINK("https://www.youtube.com/results?search_query=takeUforward+Linear+Search", "YouTube Video")
A36: 32 | B36: Todo | C36: Step 3: Arrays | D36: Easy | E36: Find the Union and Intersection of two sorted arrays | F36: Easy | G36: =HYPERLINK("https://leetcode.com/problems/intersection-of-two-arrays/", "LeetCode Practice") | H36: =HYPERLINK("https://www.youtube.com/results?search_query=takeUforward+Find+the+Union+and+Intersection+of+two+sorted+arrays", "YouTube Video")
A37: 33 | B37: Todo | C37: Step 3: Arrays | D37: Easy | E37: Find missing number in an array | F37: Easy | G37: =HYPERLINK("https://leetcode.com/problems/missing-number/", "LeetCode Practice") | H37: =HYPERLINK("https://www.youtube.com/results?search_query=takeUforward+Find+missing+number+in+an+array", "YouTube Video")
A38: 34 | B38: Todo | C38: Step 3: Arrays | D38: Easy | E38: Max Consecutive Ones | F38: Easy | G38: =HYPERLINK("https://leetcode.com/problems/max-consecutive-ones/", "LeetCode Practice") | H38: =HYPERLINK("https://www.youtube.com/results?search_query=takeUforward+Max+Consecutive+Ones", "YouTube Video")
A39: 35 | B39: Todo | C39: Step 3: Arrays | D39: Easy | E39: Find the number that appears once, and other numbers twice | F39: Easy | G39: =HYPERLINK("https://leetcode.com/problems/single-number/", "LeetCode Practice") | H39: =HYPERLINK("https://www.youtube.com/results?search_query=takeUforward+Find+the+number+that+appears+once%2C+and+other+numbers+twice", "YouTube Video")
A40: 36 | B40: Todo | C40: Step 3: Arrays | D40: Easy | E40: Longest Subarray with given Sum K (Positives) | F40: Medium | G40: =HYPERLINK("https://leetcode.com/problems/maximum-size-subarray-sum-equals-k/", "LeetCode Practice") | H40: =HYPERLINK("https://www.youtube.com/results?search_query=takeUforward+Longest+Subarray+with+given+Sum+K+%28Positives%29", "YouTube Video")
A41: 37 | B41: Todo | C41: Step 3: Arrays | D41: Easy | E41: Longest Subarray with sum K (Positives + Negatives) | F41: Medium | G41: =HYPERLINK("https://leetcode.com/problems/subarray-sum-equals-k/", "LeetCode Practice") | H41: =HYPERLINK("https://www.youtube.com/results?search_query=takeUforward+Longest+Subarray+with+sum+K+%28Positives+%2B+Negatives%29", "YouTube Video")
...
